<?xml version="1.0" encoding="utf-8"?>
<robot xmlns:xacro="http://ros.org/wiki/xacro"  name="wheel_and_caster">

    <xacro:macro name="cylinder_inertial_matrix" params="m r h">
        <inertial>
            <mass value="${m}" />
            <inertia ixx="${m*(3*r*r+h*h)/12}" ixy = "0" ixz = "0"
                iyy="${m*(3*r*r+h*h)/12}" iyz = "0"
                izz="${m*r*r/2}" /> 
        </inertial>
    </xacro:macro>
    <!-- Macro for inertia matrix -->
    <xacro:macro name="sphere_inertial_matrix" params="m r">
        <inertial>
            <mass value="${m}" />
            <inertia ixx="${2*m*r*r/5}" ixy="0" ixz="0"
                iyy="${2*m*r*r/5}" iyz="0" 
                izz="${2*m*r*r/5}" />
        </inertial>
    </xacro:macro>
    
    <xacro:property name="M_PI" value="3.1415926" />
    <!-- Defining the colors used in this robot -->
    <material name="yellow">
        <color rgba="1 0.4 0 1" />
    </material>
    <material name="black">
        <color rgba="0 0 0 0.95" />
    </material>
    <material name="gray">
        <color rgba="0.75 0.75 0.75 1" />
    </material>

    <!-- Wheel Properties -->
    <xacro:property name="wheel_length" value="0.07" />
    <xacro:property name="wheel_radius" value="0.15" />
    <xacro:property name="wheel_mass" value="1" />
    <!-- Macro for robot wheel -->
    <xacro:macro name="wheel" params="wheel_prefix parent_link *joint_pose visual">
        <link name="${wheel_prefix}_wheel_link">
            <xacro:if value="${visual}">
                <visual>
                    <origin xyz="0 0 0" rpy="${M_PI/2} 0 0" />
                    <geometry>
                        <!-- <mesh filename="package://large_base/meshes/wheel.dae" /> -->
                        <cylinder length="${wheel_length}" radius="${wheel_radius}" />
                    </geometry>
                    <material name="gray" />
                </visual>
            </xacro:if>
            <collision>
                <origin xyz="0 0 0" rpy="${M_PI/2} 0 0" />
                <geometry>
                    <cylinder radius="${wheel_radius}" length="${wheel_length}" />
                </geometry>
            </collision>
            <cylinder_inertial_matrix m="${wheel_mass}" r="${wheel_radius}" h="${wheel_length}" />
        </link>

        <joint name="${wheel_prefix}_wheel_joint" type="continuous">
            <parent link="${parent_link}" />
            <child link="${wheel_prefix}_wheel_link" />
            <xacro:insert_block name="joint_pose" />
            <axis xyz="0 1 0" />
        </joint>

        <gazebo reference="${wheel_prefix}_wheel_link">
            <material>Gazebo/Gray</material>
        </gazebo>

        <gazebo reference="${wheel_prefix}_wheel_link">
            <mu1 value="1000" />
            <mu2 value="1000" />
        </gazebo>
        <!-- Transmission is important to link the joints and the controller -->
        <transmission name="${wheel_prefix}_wheel_joint_trans">
            <type>transmission_interface/SimpleTransmission</type>
            <joint name="${wheel_prefix}_wheel_joint">
                <hardwareInterface>hardware_interface/VelocityJointInterface</hardwareInterface>
            </joint>
            <actuator name="${wheel_prefix}_wheel_motor">
                <hardwareInterface>hardware_interface/VelocityJointInterface</hardwareInterface>
                <mechanicalReduction>1</mechanicalReduction>
            </actuator>
        </transmission>
    </xacro:macro>


    <!-- caster -->
    <xacro:property name="caster_mass" value="0.2" />
    <xacro:property name="caster_radius" value="0.05" /> 
    <!-- Macro for robot caster -->
    <xacro:macro name="caster" params="caster_prefix *joint_pose parent_link visual:=true">

        <link name="${caster_prefix}_caster_link">
            <xacro:if value="${visual}">
                <visual>
                    <origin xyz="0 0 0" rpy="0 0 0" />
                    <geometry>
                        <sphere radius="${caster_radius}" />
                    </geometry>
                    <material name="black" />
                </visual>
            </xacro:if>

            <collision>
                <origin xyz="0 0 0" rpy="0 0 0" />
                <geometry>
                    <sphere radius="${caster_radius}" />
                </geometry>
            </collision>
            <sphere_inertial_matrix m="${caster_mass}" r="${caster_radius}" />
        </link>

        <gazebo reference="${caster_prefix}_caster_link">
            <material>Gazebo/Black</material>
        </gazebo>

        <gazebo reference="${caster_prefix}_caster_link">
            <mu1 value="0" />
            <mu2 value="0" />
        </gazebo>

        <joint name="${caster_prefix}_caster_joint" type="fixed">
            <xacro:insert_block name="joint_pose" />
            <parent link="${parent_link}" />
            <child link="${caster_prefix}_caster_link" />
        </joint>

    </xacro:macro>

</robot>