<?xml version="1.0"?>

<robot xmlns:xacro="http://ros.org/wiki/xacro" name="mr1000_wheel">

	<xacro:macro name="mr1000_wheel" params="wheel_prefix *joint_pose">
		<link name="${wheel_prefix}_wheel_link">
			<inertial>
				<mass value="4" />
				<origin xyz="0 0 0" />
				<inertia  ixx="0.02467" ixy="0" ixz="0" iyy="0.04411" iyz="0" izz="0.02467" />
			</inertial>
			<visual>
				<origin xyz="0 0 0" rpy="${M_PI} 0 0" />
				<geometry>
					<mesh filename="package://mr1000/meshes/wheel.dae" />
				</geometry>
			</visual>
			<collision>
				<origin xyz="0 0 0" rpy="${M_PI/2} 0 0" />
				<geometry>
					<cylinder length="${wheel_length}" radius="${wheel_radius}" />
				</geometry>
				<contact>
                         <ode>
                        <min_depth>0.001</min_depth>
                         </ode>
                    </contact>
			</collision>
		</link>

		<gazebo reference="${wheel_prefix}_wheel_link">
			<mu1 value="2.5"/>
			<mu2 value="0.9"/>
			<kp>10000000.0</kp>
			<kd>100.0</kd>
			<!-- <kp value="10000000.0" /> -->
			<!-- <kd value="1.0" /> -->
			<fdir1 value="1 0 0"/>
		</gazebo>

		<joint name="${wheel_prefix}_wheel" type="continuous">
			<parent link="base_link"/>
			<child link="${wheel_prefix}_wheel_link"/>
			<xacro:insert_block name="joint_pose"/>
			<axis xyz="0 1 0" rpy="0 0 0" />
		</joint>

		<transmission name="${wheel_prefix}_wheel_trans" type="SimpleTransmission">
			<type>transmission_interface/SimpleTransmission</type>
			<actuator name="${wheel_prefix}_wheel_motor">
				<mechanicalReduction>1</mechanicalReduction>
			</actuator>
			<joint name="${wheel_prefix}_wheel">
				<hardwareInterface>hardware_interface/VelocityJointInterface</hardwareInterface>
			</joint>
		</transmission>

	</xacro:macro>
</robot>
