<?xml version="1.0" encoding="utf-8"?>
<!-- This URDF was automatically created by SolidWorks to URDF Exporter! Originally created by Stephen Brawner (brawner@gmail.com) 
     Commit Version: 1.5.0-0-g9aa0fdb  Build Version: 1.5.7004.21443
     For more information, please see http://wiki.ros.org/sw_urdf_exporter -->
<robot
  name="mr1000">
  <link
    name="base_link">
    <inertial>
      <origin
        xyz="0.0083361 0.00033765 0.10648"
        rpy="0 0 0" />
      <mass
        value="13.336" />
      <inertia
        ixx="0.12049"
        ixy="5.9344E-06"
        ixz="-0.001006"
        iyy="0.32804"
        iyz="-7.8809E-07"
        izz="0.41342" />
    </inertial>
    <visual>
      <origin
        xyz="0 0 0.126"
        rpy="0 0 0" />
      <geometry>
        <mesh
          filename="package://mr1000/meshes/base_link.STL" />
      </geometry>
      <material
        name="">
        <color
          rgba="1 1 0 1" />
      </material>
    </visual>
    <collision>
      <origin
        xyz="0 0 0"
        rpy="0 0 0" />
      <geometry>
        <mesh
          filename="package://mr1000/meshes/base_link.STL" />
      </geometry>
    </collision>
  </link>
  <link
    name="L1">
    <inertial>
      <origin
        xyz="6.2688E-06 -0.019239 1.4959E-05"
        rpy="0 0 0" />
      <mass
        value="0.98748" />
      <inertia
        ixx="0.0094116"
        ixy="-1.3057E-08"
        ixz="3.8309E-07"
        iyy="0.017882"
        iyz="-2.274E-08"
        izz="0.0094124" />
    </inertial>
    <visual>
      <origin
        xyz="0 0 0"
        rpy="0 0 0" />
      <geometry>
        <mesh
          filename="package://mr1000/meshes/L1.STL" />
      </geometry>
      <material
        name="">
        <color
          rgba="0 0 0 1" />
      </material>
    </visual>
    <collision>
      <origin
        xyz="0 0 0"
        rpy="0 0 0" />
      <geometry>
        <mesh
          filename="package://mr1000/meshes/L1.STL" />
      </geometry>
    </collision>
  </link>
  <joint
    name="LJ1"
    type="continuous">
    <origin
      xyz="0.25721 0.271 0.165"
      rpy="0 0 0" />
    <parent
      link="base_link" />
    <child
      link="L1" />
    <axis
      xyz="0 1 0" />
    <safety_controller
      k_velocity="0" />
  </joint>
  <link
    name="L2">
    <inertial>
      <origin
        xyz="6.2688E-06 -0.019239 1.4959E-05"
        rpy="0 0 0" />
      <mass
        value="0.98748" />
      <inertia
        ixx="0.0094116"
        ixy="-1.3057E-08"
        ixz="3.8309E-07"
        iyy="0.017882"
        iyz="-2.274E-08"
        izz="0.0094124" />
    </inertial>
    <visual>
      <origin
        xyz="0 0 0"
        rpy="0 0 0" />
      <geometry>
        <mesh
          filename="package://mr1000/meshes/L1.STL" />
      </geometry>
      <material
        name="">
        <color
          rgba="0 0 0 1" />
      </material>
    </visual>
    <collision>
      <origin
        xyz="0 0 0"
        rpy="0 0 0" />
      <geometry>
        <mesh
          filename="package://mr1000/meshes/L1.STL" />
      </geometry>
    </collision>
  </link>
  <joint
    name="LJ2"
    type="continuous">
    <origin
      xyz="-0.22979 0.271 0.165"
      rpy="0 0 0" />
    <parent
      link="base_link" />
    <child
      link="L2" />
    <axis
      xyz="0 1 0" />
    <safety_controller
      k_velocity="0" />
  </joint>
  <link
    name="R1">
    <inertial>
      <origin
        xyz="6.1624E-06 -0.019239 -1.5005E-05"
        rpy="0 0 0" />
      <mass
        value="0.98748" />
      <inertia
        ixx="0.0094116"
        ixy="-7.0489E-09"
        ixz="-3.9463E-07"
        iyy="0.017882"
        iyz="2.5464E-08"
        izz="0.0094124" />
    </inertial>
    <visual>
      <origin
        xyz="0 0 0"
        rpy="0 0 0" />
      <geometry>
        <mesh
          filename="package://mr1000/meshes/L1.STL" />
      </geometry>
      <material
        name="">
        <color
          rgba="0 0 0 1" />
      </material>
    </visual>
    <collision>
      <origin
        xyz="0 0 0"
        rpy="0 0 0" />
      <geometry>
        <mesh
          filename="package://mr1000/meshes/L1.STL" />
      </geometry>
    </collision>
  </link>
  <joint
    name="RJ1"
    type="continuous">
    <origin
      xyz="0.25721 -0.271 0.165"
      rpy="3.1416 0 0" />
    <parent
      link="base_link" />
    <child
      link="R1" />
    <axis
      xyz="0 1 0" />
    <safety_controller
      k_velocity="0" />
  </joint>
  <link
    name="R2">
    <inertial>
      <origin
        xyz="6.1624E-06 -0.019239 -1.5005E-05"
        rpy="0 0 0" />
      <mass
        value="0.98748" />
      <inertia
        ixx="0.0094116"
        ixy="-7.0489E-09"
        ixz="-3.9463E-07"
        iyy="0.017882"
        iyz="2.5464E-08"
        izz="0.0094124" />
    </inertial>
    <visual>
      <origin
        xyz="0 0 0"
        rpy="0 0 0" />
      <geometry>
        <mesh
          filename="package://mr1000/meshes/L1.STL" />
      </geometry>
      <material
        name="">
        <color
          rgba="0 0 0 1" />
      </material>
    </visual>
    <collision>
      <origin
        xyz="0 0 0"
        rpy="0 0 0" />
      <geometry>
        <mesh
          filename="package://mr1000/meshes/L1.STL" />
      </geometry>
    </collision>
  </link>
  <joint
    name="RJ2"
    type="continuous">
    <origin
      xyz="-0.22979 -0.271 0.165"
      rpy="3.1416 0 0" />
    <parent
      link="base_link" />
    <child
      link="R2" />
    <axis
      xyz="0 1 0" />
    <safety_controller
      k_velocity="0" />
  </joint>
</robot>