<?xml version="1.0" encoding="utf-8"?>
<!-- This URDF was automatically created by SolidWorks to URDF Exporter! Originally created by Stephen Brawner (brawner@gmail.com) 
     Commit Version: 1.5.0-0-g9aa0fdb  Build Version: 1.5.7004.21443
     For more information, please see http://wiki.ros.org/sw_urdf_exporter -->
<robot xmlns:xacro="http://www.ros.org/wiki/xacro" name="mr1000">
  <xacro:property name="wheel_radius" value="0.16500000"/>
  <xacro:property name="wheel_length" value="0.08000000"/>

  <link name="base_link">
    <inertial>
      <origin xyz="0.0083361 0.00033765 0.10648" rpy="0 0 0" />
      <mass value="13.336" />
      <inertia
        ixx="0.12049"
        ixy="5.9344E-06"
        ixz="-0.001006"
        iyy="0.32804"
        iyz="-7.8809E-07"
        izz="0.41342" />
    </inertial>
    <visual>
      <origin xyz="0 0 0.126" rpy="0 0 0" />
      <geometry>
        <mesh filename="package://mr1000/meshes/base_linkm.STL" />
      </geometry>
      <material name="">
        <color rgba="1 1 0 1" />
      </material>
    </visual>
    <collision>
      <origin xyz="0 0 0" rpy="0 0 0" />
      <geometry>
        <mesh filename="package://mr1000/meshes/base_linkm.STL" />
      </geometry>
    </collision>
  </link>

  <!-- left front wheel -->
  <link name="L1"> 
    <inertial>
      <origin xyz="6.2688E-06 -0.019239 1.4959E-05" rpy="0 0 0" />
      <mass value="0.98748" />
      <inertia
        ixx="0.0094116"
        ixy="-1.3057E-08"
        ixz="3.8309E-07"
        iyy="0.017882"
        iyz="-2.274E-08"
        izz="0.0094124" />
    </inertial>
    <visual>
      <origin xyz="0 0 0" rpy="0 0 0" />
      <geometry>
        <mesh filename="package://mr1000/meshes/swheelr.STL" />
      </geometry>
      <material name="">
        <color rgba="0 0 0 1" />
      </material>
    </visual>
    <collision>
      <origin xyz="0 0 0" rpy="1.5708 0 0" />
      <geometry>
        <!-- <mesh filename="package://mr1000/meshes/swheelr.STL" /> -->
        <cylinder length="0.01" radius="0.165" />
      </geometry>
    </collision>
  </link>
  <joint name="LJ1" type="continuous">
    <origin xyz="0.24350 0.2702 0.165" rpy="0 0 0" />
    <parent link="base_link" />
    <child link="L1" />
    <axis xyz="0 1 0" />
    <safety_controller k_velocity="0" />
  </joint>

  <link name="L2"> <!-- left rear wheel -->
    <inertial>
      <origin xyz="6.2688E-06 -0.019239 1.4959E-05" rpy="0 0 0" />
      <mass value="0.98748" />
      <inertia
        ixx="0.0094116"
        ixy="-1.3057E-08"
        ixz="3.8309E-07"
        iyy="0.017882"
        iyz="-2.274E-08"
        izz="0.0094124" />
    </inertial>
    <visual>
      <origin xyz="0 0 0" rpy="0 0 0" />
      <geometry> 
        <mesh filename="package://mr1000/meshes/swheelr.STL" />
      </geometry>
      <material name="">
        <color rgba="0 0 0 1" />
      </material>
    </visual>
    <collision>
      <origin xyz="0 0 0" rpy="1.5708 0 0" />
      <geometry>
        <!-- <mesh filename="package://mr1000/meshes/swheelr.STL" /> -->
        <cylinder length="0.01" radius="0.165" />
      </geometry>
    </collision>
  </link>
  <joint name="LJ2" type="continuous">
    <origin xyz="-0.24350 0.2702 0.165" rpy="0 0 0" />
    <parent link="base_link" />
    <child link="L2" />
    <axis xyz="0 1 0" />
    <safety_controller k_velocity="0" />
  </joint>

  <link name="R1"> <!-- right front wheel -->
    <inertial>
      <origin xyz="6.1624E-06 -0.019239 -1.5005E-05" rpy="0 0 0" />
      <mass value="0.98748" />
      <inertia
        ixx="0.0094116"
        ixy="-7.0489E-09"
        ixz="-3.9463E-07"
        iyy="0.017882"
        iyz="2.5464E-08"
        izz="0.0094124" />
    </inertial>
    <visual>
      <origin xyz="0 0 0" rpy="0 0 0" />
      <geometry>
        <mesh filename="package://mr1000/meshes/swheelr.STL" />
      </geometry>
      <material name="">
        <color rgba="0 0 0 1" />
      </material>
    </visual>
    <collision>
      <origin xyz="0 0 0" rpy="1.5708 0 0" />
      <geometry>
        <!-- <mesh filename="package://mr1000/meshes/swheelr.STL" /> -->
        <cylinder length="0.01" radius="0.165" />
      </geometry>
    </collision>
  </link>
  <joint name="RJ1" type="continuous">
    <origin xyz="0.24350 -0.2702 0.165" rpy="3.1416  0  0  " />
    <parent link="base_link" />
    <child link="R1" />
    <axis xyz="0 -1 0" />
    <safety_controller k_velocity="0" />
  </joint>
  
  <link name="R2"> <!-- right rear wheel (antina)-->
    <inertial>
      <origin xyz="6.1624E-06 -0.019239 -1.5005E-05" rpy="0 0 0" />
      <mass value="0.98748" />
      <inertia
        ixx="0.0094116"
        ixy="-7.0489E-09"
        ixz="-3.9463E-07"
        iyy="0.017882"
        iyz="2.5464E-08"
        izz="0.0094124" />
    </inertial>
    <visual>
      <origin xyz="0 0 0" rpy="0 0 0" />
      <geometry>
        <mesh filename="package://mr1000/meshes/swheelr.STL" />
      </geometry>
      <material name="">
        <color rgba="0 0 0 1" />
      </material>
    </visual>
    <collision>
      <origin xyz="0 0 0" rpy="1.5708 0 0" />
      <geometry>
        <!-- <mesh filename="package://mr1000/meshes/swheelr.STL" /> -->
        <cylinder length="0.01" radius="0.165" />
      </geometry>
    </collision>
  </link>
  <joint name="RJ2" type="continuous">
    <origin xyz="-0.24350 -0.2702 0.165" rpy="3.1416  0  0" />
    <parent link="base_link" />
    <child link="R2" />
    <axis xyz="0 -1 0" />
    <safety_controller k_velocity="0" />
  </joint>
  
  <!-- add gazebo lib -->
  <gazebo>
    <plugin name="gazebo_ros_control" filename="libgazebo_ros_control.so">
    <robotSimType>gazebo_ros_control/DefaultRobotHWSim</robotSimType>
    <legacyModeNS>true</legacyModeNS>  
      <!-- <robotNamespace>/MYROBOT</robotNamespace> -->
    </plugin>
  </gazebo>

  <gazebo reference="base_link">                   <!-- for wheel link -->
    <material>Gazebo/Yellow</material>
  </gazebo>

  <!-- add gazebo transmission-->
  <gazebo reference="L1">                   <!-- for wheel link -->
    <mu1 value="100"/>
    <mu2 value="100"/>
    <kp value="10000000.0" />
    <kd value="1.0" />
    <fdir1 value="1 0 0"/>
    <material>Gazebo/Grey</material>
  </gazebo>
  <transmission name="L1_trans" type="SimpleTransmission">
    <type>transmission_interface/SimpleTransmission</type>
    <actuator name="L1_motor">
      <mechanicalReduction>1</mechanicalReduction>
    </actuator>
    <joint name="LJ1">    <!-- for wheel joint -->
      <hardwareInterface>hardware_interface/VelocityJointInterface</hardwareInterface>
    </joint>
  </transmission>

  <!-- add gazebo -->
  <gazebo reference="L2">                   <!-- for wheel link -->
    <mu1 value="100"/>
    <mu2 value="100"/>
    <kp value="10000000.0" />
    <kd value="1.0" />
    <fdir1 value="1 0 0"/>
    <material>Gazebo/Grey</material>
  </gazebo>
  <transmission name="L2_trans" type="SimpleTransmission">
    <type>transmission_interface/SimpleTransmission</type>
    <actuator name="L2_motor">
      <mechanicalReduction>1</mechanicalReduction>
    </actuator>
    <joint name="LJ2">    <!-- for wheel joint -->
      <hardwareInterface>hardware_interface/VelocityJointInterface</hardwareInterface>
    </joint>
  </transmission>

  <!-- add gazebo -->
  <gazebo reference="R1">                   <!-- for wheel link -->
    <mu1 value="100"/>
    <mu2 value="100"/>
    <kp value="10000000.0" />
    <kd value="1.0" />
    <fdir1 value="1 0 0"/>
    <material>Gazebo/Grey</material>
  </gazebo>
  <transmission name="R1_trans" type="SimpleTransmission">
    <type>transmission_interface/SimpleTransmission</type>
    <actuator name="R1_motor">
      <mechanicalReduction>1</mechanicalReduction>
    </actuator>
    <joint name="RJ1">    <!-- for wheel joint -->
      <hardwareInterface>hardware_interface/VelocityJointInterface</hardwareInterface>
    </joint>
  </transmission>

  <!-- add gazebo -->
  <gazebo reference="R2">                   <!-- for wheel link -->
    <mu1 value="100"/>
    <mu2 value="100"/>
    <kp value="10000000.0" />
    <kd value="1.0" />
    <fdir1 value="1 0 0"/>
    <material>Gazebo/Grey</material>
  </gazebo>
  <transmission name="R2_trans" type="SimpleTransmission">
    <type>transmission_interface/SimpleTransmission</type>
    <actuator name="R2_motor">
      <mechanicalReduction>1</mechanicalReduction>
    </actuator>
    <joint name="RJ2">    <!-- for wheel joint -->
      <hardwareInterface>hardware_interface/VelocityJointInterface</hardwareInterface>
    </joint>
  </transmission>

</robot>
